{
 "cells": [
  {
   "cell_type": "code",
   "execution_count": 1,
   "metadata": {},
   "outputs": [
    {
     "ename": "FileNotFoundError",
     "evalue": "[Errno 2] No such file or directory: 'PDB_tubuline.pdb'",
     "output_type": "error",
     "traceback": [
      "\u001b[0;31m---------------------------------------------------------------------------\u001b[0m",
      "\u001b[0;31mFileNotFoundError\u001b[0m                         Traceback (most recent call last)",
      "    \u001b[0;31m[... skipping hidden 1 frame]\u001b[0m\n",
      "\u001b[1;32m/workspaces/MDAnalysis_ISDD/run_test.ipynb Cellule 1\u001b[0m line \u001b[0;36m5\n\u001b[1;32m      <a href='vscode-notebook-cell://codespaces%2Bglowing-meme-xgjx6rqrj76f479/workspaces/MDAnalysis_ISDD/run_test.ipynb#W0sdnNjb2RlLXJlbW90ZQ%3D%3D?line=3'>4</a>\u001b[0m \u001b[39m# Creating the Universe object.\u001b[39;00m\n\u001b[0;32m----> <a href='vscode-notebook-cell://codespaces%2Bglowing-meme-xgjx6rqrj76f479/workspaces/MDAnalysis_ISDD/run_test.ipynb#W0sdnNjb2RlLXJlbW90ZQ%3D%3D?line=4'>5</a>\u001b[0m u \u001b[39m=\u001b[39m mda\u001b[39m.\u001b[39;49mUniverse(\u001b[39m'\u001b[39;49m\u001b[39mPDB_tubuline.pdb\u001b[39;49m\u001b[39m'\u001b[39;49m, \u001b[39m'\u001b[39;49m\u001b[39mtrajectoire_tubuline.dcd\u001b[39;49m\u001b[39m'\u001b[39;49m)\n\u001b[1;32m      <a href='vscode-notebook-cell://codespaces%2Bglowing-meme-xgjx6rqrj76f479/workspaces/MDAnalysis_ISDD/run_test.ipynb#W0sdnNjb2RlLXJlbW90ZQ%3D%3D?line=6'>7</a>\u001b[0m \u001b[39m# Create a selection of atoms to work with.\u001b[39;00m\n",
      "File \u001b[0;32m~/.python/current/lib/python3.10/site-packages/MDAnalysis/core/universe.py:356\u001b[0m, in \u001b[0;36mUniverse.__init__\u001b[0;34m(self, topology, all_coordinates, format, topology_format, transformations, guess_bonds, vdwradii, fudge_factor, lower_bound, in_memory, in_memory_step, *coordinates, **kwargs)\u001b[0m\n\u001b[1;32m    355\u001b[0m     \u001b[39mself\u001b[39m\u001b[39m.\u001b[39mfilename \u001b[39m=\u001b[39m _check_file_like(topology)\n\u001b[0;32m--> 356\u001b[0m     topology \u001b[39m=\u001b[39m _topology_from_file_like(\u001b[39mself\u001b[39;49m\u001b[39m.\u001b[39;49mfilename,\n\u001b[1;32m    357\u001b[0m                                         topology_format\u001b[39m=\u001b[39;49mtopology_format,\n\u001b[1;32m    358\u001b[0m                                         \u001b[39m*\u001b[39;49m\u001b[39m*\u001b[39;49mkwargs)\n\u001b[1;32m    360\u001b[0m \u001b[39mif\u001b[39;00m topology \u001b[39mis\u001b[39;00m \u001b[39mnot\u001b[39;00m \u001b[39mNone\u001b[39;00m:\n",
      "File \u001b[0;32m~/.python/current/lib/python3.10/site-packages/MDAnalysis/core/universe.py:118\u001b[0m, in \u001b[0;36m_topology_from_file_like\u001b[0;34m(topology_file, topology_format, **kwargs)\u001b[0m\n\u001b[1;32m    115\u001b[0m \u001b[39mif\u001b[39;00m (err\u001b[39m.\u001b[39merrno \u001b[39mis\u001b[39;00m \u001b[39mnot\u001b[39;00m \u001b[39mNone\u001b[39;00m \u001b[39mand\u001b[39;00m\n\u001b[1;32m    116\u001b[0m     errno\u001b[39m.\u001b[39merrorcode[err\u001b[39m.\u001b[39merrno] \u001b[39min\u001b[39;00m [\u001b[39m'\u001b[39m\u001b[39mENOENT\u001b[39m\u001b[39m'\u001b[39m, \u001b[39m'\u001b[39m\u001b[39mEACCES\u001b[39m\u001b[39m'\u001b[39m]):\n\u001b[1;32m    117\u001b[0m     \u001b[39m# Runs if the error is propagated due to no permission / file not found\u001b[39;00m\n\u001b[0;32m--> 118\u001b[0m     \u001b[39mraise\u001b[39;00m sys\u001b[39m.\u001b[39mexc_info()[\u001b[39m1\u001b[39m] \u001b[39mfrom\u001b[39;00m \u001b[39merr\u001b[39;00m\n\u001b[1;32m    119\u001b[0m \u001b[39melse\u001b[39;00m:\n\u001b[1;32m    120\u001b[0m     \u001b[39m# Runs when the parser fails\u001b[39;00m\n",
      "File \u001b[0;32m~/.python/current/lib/python3.10/site-packages/MDAnalysis/core/universe.py:110\u001b[0m, in \u001b[0;36m_topology_from_file_like\u001b[0;34m(topology_file, topology_format, **kwargs)\u001b[0m\n\u001b[1;32m    109\u001b[0m     \u001b[39mwith\u001b[39;00m parser(topology_file) \u001b[39mas\u001b[39;00m p:\n\u001b[0;32m--> 110\u001b[0m         topology \u001b[39m=\u001b[39m p\u001b[39m.\u001b[39;49mparse(\u001b[39m*\u001b[39;49m\u001b[39m*\u001b[39;49mkwargs)\n\u001b[1;32m    111\u001b[0m \u001b[39mexcept\u001b[39;00m (\u001b[39mIOError\u001b[39;00m, \u001b[39mOSError\u001b[39;00m) \u001b[39mas\u001b[39;00m err:\n\u001b[1;32m    112\u001b[0m     \u001b[39m# There are 2 kinds of errors that might be raised here:\u001b[39;00m\n\u001b[1;32m    113\u001b[0m     \u001b[39m# one because the file isn't present\u001b[39;00m\n\u001b[1;32m    114\u001b[0m     \u001b[39m# or the permissions are bad, second when the parser fails\u001b[39;00m\n",
      "File \u001b[0;32m~/.python/current/lib/python3.10/site-packages/MDAnalysis/topology/PDBParser.py:210\u001b[0m, in \u001b[0;36mPDBParser.parse\u001b[0;34m(self, **kwargs)\u001b[0m\n\u001b[1;32m    204\u001b[0m \u001b[39m\u001b[39m\u001b[39m\"\"\"Parse atom information from PDB file\u001b[39;00m\n\u001b[1;32m    205\u001b[0m \n\u001b[1;32m    206\u001b[0m \u001b[39mReturns\u001b[39;00m\n\u001b[1;32m    207\u001b[0m \u001b[39m-------\u001b[39;00m\n\u001b[1;32m    208\u001b[0m \u001b[39mMDAnalysis Topology object\u001b[39;00m\n\u001b[1;32m    209\u001b[0m \u001b[39m\"\"\"\u001b[39;00m\n\u001b[0;32m--> 210\u001b[0m top \u001b[39m=\u001b[39m \u001b[39mself\u001b[39;49m\u001b[39m.\u001b[39;49m_parseatoms()\n\u001b[1;32m    212\u001b[0m \u001b[39mtry\u001b[39;00m:\n",
      "File \u001b[0;32m~/.python/current/lib/python3.10/site-packages/MDAnalysis/topology/PDBParser.py:247\u001b[0m, in \u001b[0;36mPDBParser._parseatoms\u001b[0;34m(self)\u001b[0m\n\u001b[1;32m    246\u001b[0m last_wrapped_serial \u001b[39m=\u001b[39m \u001b[39m100000\u001b[39m  \u001b[39m# if serials wrap, start from here\u001b[39;00m\n\u001b[0;32m--> 247\u001b[0m \u001b[39mwith\u001b[39;00m util\u001b[39m.\u001b[39mopenany(\u001b[39mself\u001b[39m\u001b[39m.\u001b[39mfilename) \u001b[39mas\u001b[39;00m f:\n\u001b[1;32m    248\u001b[0m     \u001b[39mfor\u001b[39;00m line \u001b[39min\u001b[39;00m f:\n",
      "File \u001b[0;32m~/.python/current/lib/python3.10/contextlib.py:135\u001b[0m, in \u001b[0;36m_GeneratorContextManager.__enter__\u001b[0;34m(self)\u001b[0m\n\u001b[1;32m    134\u001b[0m \u001b[39mtry\u001b[39;00m:\n\u001b[0;32m--> 135\u001b[0m     \u001b[39mreturn\u001b[39;00m \u001b[39mnext\u001b[39;49m(\u001b[39mself\u001b[39;49m\u001b[39m.\u001b[39;49mgen)\n\u001b[1;32m    136\u001b[0m \u001b[39mexcept\u001b[39;00m \u001b[39mStopIteration\u001b[39;00m:\n",
      "File \u001b[0;32m~/.python/current/lib/python3.10/site-packages/MDAnalysis/lib/util.py:318\u001b[0m, in \u001b[0;36mopenany\u001b[0;34m(datasource, mode, reset)\u001b[0m\n\u001b[1;32m    276\u001b[0m \u001b[39m\u001b[39m\u001b[39m\"\"\"Context manager for :func:`anyopen`.\u001b[39;00m\n\u001b[1;32m    277\u001b[0m \n\u001b[1;32m    278\u001b[0m \u001b[39mOpen the `datasource` and close it when the context of the :keyword:`with`\u001b[39;00m\n\u001b[0;32m   (...)\u001b[0m\n\u001b[1;32m    316\u001b[0m \u001b[39m:func:`anyopen`\u001b[39;00m\n\u001b[1;32m    317\u001b[0m \u001b[39m\"\"\"\u001b[39;00m\n\u001b[0;32m--> 318\u001b[0m stream \u001b[39m=\u001b[39m anyopen(datasource, mode\u001b[39m=\u001b[39;49mmode, reset\u001b[39m=\u001b[39;49mreset)\n\u001b[1;32m    319\u001b[0m \u001b[39mtry\u001b[39;00m:\n",
      "File \u001b[0;32m~/.python/current/lib/python3.10/site-packages/MDAnalysis/lib/util.py:398\u001b[0m, in \u001b[0;36manyopen\u001b[0;34m(datasource, mode, reset)\u001b[0m\n\u001b[1;32m    397\u001b[0m openfunc \u001b[39m=\u001b[39m read_handlers[ext]\n\u001b[0;32m--> 398\u001b[0m stream \u001b[39m=\u001b[39m _get_stream(datasource, openfunc, mode\u001b[39m=\u001b[39;49mmode)\n\u001b[1;32m    399\u001b[0m \u001b[39mif\u001b[39;00m stream \u001b[39mis\u001b[39;00m \u001b[39mnot\u001b[39;00m \u001b[39mNone\u001b[39;00m:\n",
      "File \u001b[0;32m~/.python/current/lib/python3.10/site-packages/MDAnalysis/lib/util.py:440\u001b[0m, in \u001b[0;36m_get_stream\u001b[0;34m(filename, openfunction, mode)\u001b[0m\n\u001b[1;32m    439\u001b[0m \u001b[39mif\u001b[39;00m errno\u001b[39m.\u001b[39merrorcode[err\u001b[39m.\u001b[39merrno] \u001b[39min\u001b[39;00m [\u001b[39m'\u001b[39m\u001b[39mENOENT\u001b[39m\u001b[39m'\u001b[39m, \u001b[39m'\u001b[39m\u001b[39mEACCES\u001b[39m\u001b[39m'\u001b[39m]:\n\u001b[0;32m--> 440\u001b[0m     \u001b[39mraise\u001b[39;00m sys\u001b[39m.\u001b[39mexc_info()[\u001b[39m1\u001b[39m] \u001b[39mfrom\u001b[39;00m \u001b[39merr\u001b[39;00m\n\u001b[1;32m    441\u001b[0m \u001b[39mreturn\u001b[39;00m \u001b[39mNone\u001b[39;00m\n",
      "File \u001b[0;32m~/.python/current/lib/python3.10/site-packages/MDAnalysis/lib/util.py:434\u001b[0m, in \u001b[0;36m_get_stream\u001b[0;34m(filename, openfunction, mode)\u001b[0m\n\u001b[1;32m    433\u001b[0m \u001b[39mtry\u001b[39;00m:\n\u001b[0;32m--> 434\u001b[0m     stream \u001b[39m=\u001b[39m openfunction(filename, mode\u001b[39m=\u001b[39;49mmode)\n\u001b[1;32m    435\u001b[0m \u001b[39mexcept\u001b[39;00m (\u001b[39mIOError\u001b[39;00m, \u001b[39mOSError\u001b[39;00m) \u001b[39mas\u001b[39;00m err:\n\u001b[1;32m    436\u001b[0m     \u001b[39m# An exception might be raised due to two reasons, first the openfunction is unable to open the file, in this\u001b[39;00m\n\u001b[1;32m    437\u001b[0m     \u001b[39m# case we have to ignore the error and return None. Second is when openfunction can't open the file because\u001b[39;00m\n\u001b[1;32m    438\u001b[0m     \u001b[39m# either the file isn't there or the permissions don't allow access.\u001b[39;00m\n",
      "File \u001b[0;32m~/.python/current/lib/python3.10/site-packages/MDAnalysis/lib/picklable_file_io.py:478\u001b[0m, in \u001b[0;36mbz2_pickle_open\u001b[0;34m(name, mode)\u001b[0m\n\u001b[1;32m    477\u001b[0m bz_mode \u001b[39m=\u001b[39m mode\u001b[39m.\u001b[39mreplace(\u001b[39m\"\u001b[39m\u001b[39mt\u001b[39m\u001b[39m\"\u001b[39m, \u001b[39m\"\u001b[39m\u001b[39m\"\u001b[39m)\n\u001b[0;32m--> 478\u001b[0m binary_file \u001b[39m=\u001b[39m BZ2Picklable(name, bz_mode)\n\u001b[1;32m    479\u001b[0m \u001b[39mif\u001b[39;00m \u001b[39m\"\u001b[39m\u001b[39mt\u001b[39m\u001b[39m\"\u001b[39m \u001b[39min\u001b[39;00m mode:\n",
      "File \u001b[0;32m~/.python/current/lib/python3.10/site-packages/MDAnalysis/lib/picklable_file_io.py:266\u001b[0m, in \u001b[0;36mBZ2Picklable.__init__\u001b[0;34m(self, name, mode)\u001b[0m\n\u001b[1;32m    265\u001b[0m \u001b[39mself\u001b[39m\u001b[39m.\u001b[39m_bz_mode \u001b[39m=\u001b[39m mode\n\u001b[0;32m--> 266\u001b[0m \u001b[39msuper\u001b[39;49m()\u001b[39m.\u001b[39;49m\u001b[39m__init__\u001b[39;49m(name, mode)\n",
      "File \u001b[0;32m~/.python/current/lib/python3.10/bz2.py:81\u001b[0m, in \u001b[0;36mBZ2File.__init__\u001b[0;34m(self, filename, mode, compresslevel)\u001b[0m\n\u001b[1;32m     80\u001b[0m \u001b[39mif\u001b[39;00m \u001b[39misinstance\u001b[39m(filename, (\u001b[39mstr\u001b[39m, \u001b[39mbytes\u001b[39m, os\u001b[39m.\u001b[39mPathLike)):\n\u001b[0;32m---> 81\u001b[0m     \u001b[39mself\u001b[39m\u001b[39m.\u001b[39m_fp \u001b[39m=\u001b[39m _builtin_open(filename, mode)\n\u001b[1;32m     82\u001b[0m     \u001b[39mself\u001b[39m\u001b[39m.\u001b[39m_closefp \u001b[39m=\u001b[39m \u001b[39mTrue\u001b[39;00m\n",
      "\u001b[0;31mFileNotFoundError\u001b[0m: [Errno 2] No such file or directory: 'PDB_tubuline.pdb'",
      "\nThe above exception was the direct cause of the following exception:\n",
      "\u001b[0;31mFileNotFoundError\u001b[0m                         Traceback (most recent call last)",
      "    \u001b[0;31m[... skipping hidden 1 frame]\u001b[0m\n",
      "\u001b[1;32m/workspaces/MDAnalysis_ISDD/run_test.ipynb Cellule 1\u001b[0m line \u001b[0;36m5\n\u001b[1;32m      <a href='vscode-notebook-cell://codespaces%2Bglowing-meme-xgjx6rqrj76f479/workspaces/MDAnalysis_ISDD/run_test.ipynb#W0sdnNjb2RlLXJlbW90ZQ%3D%3D?line=3'>4</a>\u001b[0m \u001b[39m# Creating the Universe object.\u001b[39;00m\n\u001b[0;32m----> <a href='vscode-notebook-cell://codespaces%2Bglowing-meme-xgjx6rqrj76f479/workspaces/MDAnalysis_ISDD/run_test.ipynb#W0sdnNjb2RlLXJlbW90ZQ%3D%3D?line=4'>5</a>\u001b[0m u \u001b[39m=\u001b[39m mda\u001b[39m.\u001b[39;49mUniverse(\u001b[39m'\u001b[39;49m\u001b[39mPDB_tubuline.pdb\u001b[39;49m\u001b[39m'\u001b[39;49m, \u001b[39m'\u001b[39;49m\u001b[39mtrajectoire_tubuline.dcd\u001b[39;49m\u001b[39m'\u001b[39;49m)\n\u001b[1;32m      <a href='vscode-notebook-cell://codespaces%2Bglowing-meme-xgjx6rqrj76f479/workspaces/MDAnalysis_ISDD/run_test.ipynb#W0sdnNjb2RlLXJlbW90ZQ%3D%3D?line=6'>7</a>\u001b[0m \u001b[39m# Create a selection of atoms to work with.\u001b[39;00m\n",
      "File \u001b[0;32m~/.python/current/lib/python3.10/site-packages/MDAnalysis/core/universe.py:356\u001b[0m, in \u001b[0;36mUniverse.__init__\u001b[0;34m(self, topology, all_coordinates, format, topology_format, transformations, guess_bonds, vdwradii, fudge_factor, lower_bound, in_memory, in_memory_step, *coordinates, **kwargs)\u001b[0m\n\u001b[1;32m    355\u001b[0m     \u001b[39mself\u001b[39m\u001b[39m.\u001b[39mfilename \u001b[39m=\u001b[39m _check_file_like(topology)\n\u001b[0;32m--> 356\u001b[0m     topology \u001b[39m=\u001b[39m _topology_from_file_like(\u001b[39mself\u001b[39;49m\u001b[39m.\u001b[39;49mfilename,\n\u001b[1;32m    357\u001b[0m                                         topology_format\u001b[39m=\u001b[39;49mtopology_format,\n\u001b[1;32m    358\u001b[0m                                         \u001b[39m*\u001b[39;49m\u001b[39m*\u001b[39;49mkwargs)\n\u001b[1;32m    360\u001b[0m \u001b[39mif\u001b[39;00m topology \u001b[39mis\u001b[39;00m \u001b[39mnot\u001b[39;00m \u001b[39mNone\u001b[39;00m:\n",
      "File \u001b[0;32m~/.python/current/lib/python3.10/site-packages/MDAnalysis/core/universe.py:118\u001b[0m, in \u001b[0;36m_topology_from_file_like\u001b[0;34m(topology_file, topology_format, **kwargs)\u001b[0m\n\u001b[1;32m    115\u001b[0m \u001b[39mif\u001b[39;00m (err\u001b[39m.\u001b[39merrno \u001b[39mis\u001b[39;00m \u001b[39mnot\u001b[39;00m \u001b[39mNone\u001b[39;00m \u001b[39mand\u001b[39;00m\n\u001b[1;32m    116\u001b[0m     errno\u001b[39m.\u001b[39merrorcode[err\u001b[39m.\u001b[39merrno] \u001b[39min\u001b[39;00m [\u001b[39m'\u001b[39m\u001b[39mENOENT\u001b[39m\u001b[39m'\u001b[39m, \u001b[39m'\u001b[39m\u001b[39mEACCES\u001b[39m\u001b[39m'\u001b[39m]):\n\u001b[1;32m    117\u001b[0m     \u001b[39m# Runs if the error is propagated due to no permission / file not found\u001b[39;00m\n\u001b[0;32m--> 118\u001b[0m     \u001b[39mraise\u001b[39;00m sys\u001b[39m.\u001b[39mexc_info()[\u001b[39m1\u001b[39m] \u001b[39mfrom\u001b[39;00m \u001b[39merr\u001b[39;00m\n\u001b[1;32m    119\u001b[0m \u001b[39melse\u001b[39;00m:\n\u001b[1;32m    120\u001b[0m     \u001b[39m# Runs when the parser fails\u001b[39;00m\n",
      "File \u001b[0;32m~/.python/current/lib/python3.10/site-packages/MDAnalysis/core/universe.py:110\u001b[0m, in \u001b[0;36m_topology_from_file_like\u001b[0;34m(topology_file, topology_format, **kwargs)\u001b[0m\n\u001b[1;32m    109\u001b[0m     \u001b[39mwith\u001b[39;00m parser(topology_file) \u001b[39mas\u001b[39;00m p:\n\u001b[0;32m--> 110\u001b[0m         topology \u001b[39m=\u001b[39m p\u001b[39m.\u001b[39;49mparse(\u001b[39m*\u001b[39;49m\u001b[39m*\u001b[39;49mkwargs)\n\u001b[1;32m    111\u001b[0m \u001b[39mexcept\u001b[39;00m (\u001b[39mIOError\u001b[39;00m, \u001b[39mOSError\u001b[39;00m) \u001b[39mas\u001b[39;00m err:\n\u001b[1;32m    112\u001b[0m     \u001b[39m# There are 2 kinds of errors that might be raised here:\u001b[39;00m\n\u001b[1;32m    113\u001b[0m     \u001b[39m# one because the file isn't present\u001b[39;00m\n\u001b[1;32m    114\u001b[0m     \u001b[39m# or the permissions are bad, second when the parser fails\u001b[39;00m\n",
      "File \u001b[0;32m~/.python/current/lib/python3.10/site-packages/MDAnalysis/topology/PDBParser.py:210\u001b[0m, in \u001b[0;36mPDBParser.parse\u001b[0;34m(self, **kwargs)\u001b[0m\n\u001b[1;32m    204\u001b[0m \u001b[39m\u001b[39m\u001b[39m\"\"\"Parse atom information from PDB file\u001b[39;00m\n\u001b[1;32m    205\u001b[0m \n\u001b[1;32m    206\u001b[0m \u001b[39mReturns\u001b[39;00m\n\u001b[1;32m    207\u001b[0m \u001b[39m-------\u001b[39;00m\n\u001b[1;32m    208\u001b[0m \u001b[39mMDAnalysis Topology object\u001b[39;00m\n\u001b[1;32m    209\u001b[0m \u001b[39m\"\"\"\u001b[39;00m\n\u001b[0;32m--> 210\u001b[0m top \u001b[39m=\u001b[39m \u001b[39mself\u001b[39;49m\u001b[39m.\u001b[39;49m_parseatoms()\n\u001b[1;32m    212\u001b[0m \u001b[39mtry\u001b[39;00m:\n",
      "File \u001b[0;32m~/.python/current/lib/python3.10/site-packages/MDAnalysis/topology/PDBParser.py:247\u001b[0m, in \u001b[0;36mPDBParser._parseatoms\u001b[0;34m(self)\u001b[0m\n\u001b[1;32m    246\u001b[0m last_wrapped_serial \u001b[39m=\u001b[39m \u001b[39m100000\u001b[39m  \u001b[39m# if serials wrap, start from here\u001b[39;00m\n\u001b[0;32m--> 247\u001b[0m \u001b[39mwith\u001b[39;00m util\u001b[39m.\u001b[39mopenany(\u001b[39mself\u001b[39m\u001b[39m.\u001b[39mfilename) \u001b[39mas\u001b[39;00m f:\n\u001b[1;32m    248\u001b[0m     \u001b[39mfor\u001b[39;00m line \u001b[39min\u001b[39;00m f:\n",
      "File \u001b[0;32m~/.python/current/lib/python3.10/contextlib.py:135\u001b[0m, in \u001b[0;36m_GeneratorContextManager.__enter__\u001b[0;34m(self)\u001b[0m\n\u001b[1;32m    134\u001b[0m \u001b[39mtry\u001b[39;00m:\n\u001b[0;32m--> 135\u001b[0m     \u001b[39mreturn\u001b[39;00m \u001b[39mnext\u001b[39;49m(\u001b[39mself\u001b[39;49m\u001b[39m.\u001b[39;49mgen)\n\u001b[1;32m    136\u001b[0m \u001b[39mexcept\u001b[39;00m \u001b[39mStopIteration\u001b[39;00m:\n",
      "File \u001b[0;32m~/.python/current/lib/python3.10/site-packages/MDAnalysis/lib/util.py:318\u001b[0m, in \u001b[0;36mopenany\u001b[0;34m(datasource, mode, reset)\u001b[0m\n\u001b[1;32m    276\u001b[0m \u001b[39m\u001b[39m\u001b[39m\"\"\"Context manager for :func:`anyopen`.\u001b[39;00m\n\u001b[1;32m    277\u001b[0m \n\u001b[1;32m    278\u001b[0m \u001b[39mOpen the `datasource` and close it when the context of the :keyword:`with`\u001b[39;00m\n\u001b[0;32m   (...)\u001b[0m\n\u001b[1;32m    316\u001b[0m \u001b[39m:func:`anyopen`\u001b[39;00m\n\u001b[1;32m    317\u001b[0m \u001b[39m\"\"\"\u001b[39;00m\n\u001b[0;32m--> 318\u001b[0m stream \u001b[39m=\u001b[39m anyopen(datasource, mode\u001b[39m=\u001b[39;49mmode, reset\u001b[39m=\u001b[39;49mreset)\n\u001b[1;32m    319\u001b[0m \u001b[39mtry\u001b[39;00m:\n",
      "File \u001b[0;32m~/.python/current/lib/python3.10/site-packages/MDAnalysis/lib/util.py:398\u001b[0m, in \u001b[0;36manyopen\u001b[0;34m(datasource, mode, reset)\u001b[0m\n\u001b[1;32m    397\u001b[0m openfunc \u001b[39m=\u001b[39m read_handlers[ext]\n\u001b[0;32m--> 398\u001b[0m stream \u001b[39m=\u001b[39m _get_stream(datasource, openfunc, mode\u001b[39m=\u001b[39;49mmode)\n\u001b[1;32m    399\u001b[0m \u001b[39mif\u001b[39;00m stream \u001b[39mis\u001b[39;00m \u001b[39mnot\u001b[39;00m \u001b[39mNone\u001b[39;00m:\n",
      "File \u001b[0;32m~/.python/current/lib/python3.10/site-packages/MDAnalysis/lib/util.py:440\u001b[0m, in \u001b[0;36m_get_stream\u001b[0;34m(filename, openfunction, mode)\u001b[0m\n\u001b[1;32m    439\u001b[0m \u001b[39mif\u001b[39;00m errno\u001b[39m.\u001b[39merrorcode[err\u001b[39m.\u001b[39merrno] \u001b[39min\u001b[39;00m [\u001b[39m'\u001b[39m\u001b[39mENOENT\u001b[39m\u001b[39m'\u001b[39m, \u001b[39m'\u001b[39m\u001b[39mEACCES\u001b[39m\u001b[39m'\u001b[39m]:\n\u001b[0;32m--> 440\u001b[0m     \u001b[39mraise\u001b[39;00m sys\u001b[39m.\u001b[39mexc_info()[\u001b[39m1\u001b[39m] \u001b[39mfrom\u001b[39;00m \u001b[39merr\u001b[39;00m\n\u001b[1;32m    441\u001b[0m \u001b[39mreturn\u001b[39;00m \u001b[39mNone\u001b[39;00m\n",
      "File \u001b[0;32m~/.python/current/lib/python3.10/site-packages/MDAnalysis/lib/util.py:434\u001b[0m, in \u001b[0;36m_get_stream\u001b[0;34m(filename, openfunction, mode)\u001b[0m\n\u001b[1;32m    433\u001b[0m \u001b[39mtry\u001b[39;00m:\n\u001b[0;32m--> 434\u001b[0m     stream \u001b[39m=\u001b[39m openfunction(filename, mode\u001b[39m=\u001b[39;49mmode)\n\u001b[1;32m    435\u001b[0m \u001b[39mexcept\u001b[39;00m (\u001b[39mIOError\u001b[39;00m, \u001b[39mOSError\u001b[39;00m) \u001b[39mas\u001b[39;00m err:\n\u001b[1;32m    436\u001b[0m     \u001b[39m# An exception might be raised due to two reasons, first the openfunction is unable to open the file, in this\u001b[39;00m\n\u001b[1;32m    437\u001b[0m     \u001b[39m# case we have to ignore the error and return None. Second is when openfunction can't open the file because\u001b[39;00m\n\u001b[1;32m    438\u001b[0m     \u001b[39m# either the file isn't there or the permissions don't allow access.\u001b[39;00m\n",
      "File \u001b[0;32m~/.python/current/lib/python3.10/site-packages/MDAnalysis/lib/picklable_file_io.py:478\u001b[0m, in \u001b[0;36mbz2_pickle_open\u001b[0;34m(name, mode)\u001b[0m\n\u001b[1;32m    477\u001b[0m bz_mode \u001b[39m=\u001b[39m mode\u001b[39m.\u001b[39mreplace(\u001b[39m\"\u001b[39m\u001b[39mt\u001b[39m\u001b[39m\"\u001b[39m, \u001b[39m\"\u001b[39m\u001b[39m\"\u001b[39m)\n\u001b[0;32m--> 478\u001b[0m binary_file \u001b[39m=\u001b[39m BZ2Picklable(name, bz_mode)\n\u001b[1;32m    479\u001b[0m \u001b[39mif\u001b[39;00m \u001b[39m\"\u001b[39m\u001b[39mt\u001b[39m\u001b[39m\"\u001b[39m \u001b[39min\u001b[39;00m mode:\n",
      "File \u001b[0;32m~/.python/current/lib/python3.10/site-packages/MDAnalysis/lib/picklable_file_io.py:266\u001b[0m, in \u001b[0;36mBZ2Picklable.__init__\u001b[0;34m(self, name, mode)\u001b[0m\n\u001b[1;32m    265\u001b[0m \u001b[39mself\u001b[39m\u001b[39m.\u001b[39m_bz_mode \u001b[39m=\u001b[39m mode\n\u001b[0;32m--> 266\u001b[0m \u001b[39msuper\u001b[39;49m()\u001b[39m.\u001b[39;49m\u001b[39m__init__\u001b[39;49m(name, mode)\n",
      "File \u001b[0;32m~/.python/current/lib/python3.10/bz2.py:81\u001b[0m, in \u001b[0;36mBZ2File.__init__\u001b[0;34m(self, filename, mode, compresslevel)\u001b[0m\n\u001b[1;32m     80\u001b[0m \u001b[39mif\u001b[39;00m \u001b[39misinstance\u001b[39m(filename, (\u001b[39mstr\u001b[39m, \u001b[39mbytes\u001b[39m, os\u001b[39m.\u001b[39mPathLike)):\n\u001b[0;32m---> 81\u001b[0m     \u001b[39mself\u001b[39m\u001b[39m.\u001b[39m_fp \u001b[39m=\u001b[39m _builtin_open(filename, mode)\n\u001b[1;32m     82\u001b[0m     \u001b[39mself\u001b[39m\u001b[39m.\u001b[39m_closefp \u001b[39m=\u001b[39m \u001b[39mTrue\u001b[39;00m\n",
      "\u001b[0;31mFileNotFoundError\u001b[0m: [Errno 2] No such file or directory: 'PDB_tubuline.pdb'",
      "\nThe above exception was the direct cause of the following exception:\n",
      "\u001b[0;31mFileNotFoundError\u001b[0m                         Traceback (most recent call last)",
      "\u001b[1;32m/workspaces/MDAnalysis_ISDD/run_test.ipynb Cellule 1\u001b[0m line \u001b[0;36m5\n\u001b[1;32m      <a href='vscode-notebook-cell://codespaces%2Bglowing-meme-xgjx6rqrj76f479/workspaces/MDAnalysis_ISDD/run_test.ipynb#W0sdnNjb2RlLXJlbW90ZQ%3D%3D?line=1'>2</a>\u001b[0m \u001b[39mimport\u001b[39;00m \u001b[39mMDAnalysis\u001b[39;00m \u001b[39mas\u001b[39;00m \u001b[39mmda\u001b[39;00m\n\u001b[1;32m      <a href='vscode-notebook-cell://codespaces%2Bglowing-meme-xgjx6rqrj76f479/workspaces/MDAnalysis_ISDD/run_test.ipynb#W0sdnNjb2RlLXJlbW90ZQ%3D%3D?line=3'>4</a>\u001b[0m \u001b[39m# Creating the Universe object.\u001b[39;00m\n\u001b[0;32m----> <a href='vscode-notebook-cell://codespaces%2Bglowing-meme-xgjx6rqrj76f479/workspaces/MDAnalysis_ISDD/run_test.ipynb#W0sdnNjb2RlLXJlbW90ZQ%3D%3D?line=4'>5</a>\u001b[0m u \u001b[39m=\u001b[39m mda\u001b[39m.\u001b[39;49mUniverse(\u001b[39m'\u001b[39;49m\u001b[39mPDB_tubuline.pdb\u001b[39;49m\u001b[39m'\u001b[39;49m, \u001b[39m'\u001b[39;49m\u001b[39mtrajectoire_tubuline.dcd\u001b[39;49m\u001b[39m'\u001b[39;49m)\n\u001b[1;32m      <a href='vscode-notebook-cell://codespaces%2Bglowing-meme-xgjx6rqrj76f479/workspaces/MDAnalysis_ISDD/run_test.ipynb#W0sdnNjb2RlLXJlbW90ZQ%3D%3D?line=6'>7</a>\u001b[0m \u001b[39m# Create a selection of atoms to work with.\u001b[39;00m\n\u001b[1;32m      <a href='vscode-notebook-cell://codespaces%2Bglowing-meme-xgjx6rqrj76f479/workspaces/MDAnalysis_ISDD/run_test.ipynb#W0sdnNjb2RlLXJlbW90ZQ%3D%3D?line=7'>8</a>\u001b[0m ag \u001b[39m=\u001b[39m u\u001b[39m.\u001b[39matoms\u001b[39m.\u001b[39mselect_atoms(\u001b[39m'\u001b[39m\u001b[39mbackbone\u001b[39m\u001b[39m'\u001b[39m)\n",
      "File \u001b[0;32m~/.python/current/lib/python3.10/site-packages/MDAnalysis/core/universe.py:356\u001b[0m, in \u001b[0;36mUniverse.__init__\u001b[0;34m(self, topology, all_coordinates, format, topology_format, transformations, guess_bonds, vdwradii, fudge_factor, lower_bound, in_memory, in_memory_step, *coordinates, **kwargs)\u001b[0m\n\u001b[1;32m    354\u001b[0m \u001b[39mif\u001b[39;00m \u001b[39mnot\u001b[39;00m \u001b[39misinstance\u001b[39m(topology, Topology) \u001b[39mand\u001b[39;00m \u001b[39mnot\u001b[39;00m topology \u001b[39mis\u001b[39;00m \u001b[39mNone\u001b[39;00m:\n\u001b[1;32m    355\u001b[0m     \u001b[39mself\u001b[39m\u001b[39m.\u001b[39mfilename \u001b[39m=\u001b[39m _check_file_like(topology)\n\u001b[0;32m--> 356\u001b[0m     topology \u001b[39m=\u001b[39m _topology_from_file_like(\u001b[39mself\u001b[39;49m\u001b[39m.\u001b[39;49mfilename,\n\u001b[1;32m    357\u001b[0m                                         topology_format\u001b[39m=\u001b[39;49mtopology_format,\n\u001b[1;32m    358\u001b[0m                                         \u001b[39m*\u001b[39;49m\u001b[39m*\u001b[39;49mkwargs)\n\u001b[1;32m    360\u001b[0m \u001b[39mif\u001b[39;00m topology \u001b[39mis\u001b[39;00m \u001b[39mnot\u001b[39;00m \u001b[39mNone\u001b[39;00m:\n\u001b[1;32m    361\u001b[0m     \u001b[39mself\u001b[39m\u001b[39m.\u001b[39m_topology \u001b[39m=\u001b[39m topology\n",
      "File \u001b[0;32m~/.python/current/lib/python3.10/site-packages/MDAnalysis/core/universe.py:118\u001b[0m, in \u001b[0;36m_topology_from_file_like\u001b[0;34m(topology_file, topology_format, **kwargs)\u001b[0m\n\u001b[1;32m    111\u001b[0m \u001b[39mexcept\u001b[39;00m (\u001b[39mIOError\u001b[39;00m, \u001b[39mOSError\u001b[39;00m) \u001b[39mas\u001b[39;00m err:\n\u001b[1;32m    112\u001b[0m     \u001b[39m# There are 2 kinds of errors that might be raised here:\u001b[39;00m\n\u001b[1;32m    113\u001b[0m     \u001b[39m# one because the file isn't present\u001b[39;00m\n\u001b[1;32m    114\u001b[0m     \u001b[39m# or the permissions are bad, second when the parser fails\u001b[39;00m\n\u001b[1;32m    115\u001b[0m     \u001b[39mif\u001b[39;00m (err\u001b[39m.\u001b[39merrno \u001b[39mis\u001b[39;00m \u001b[39mnot\u001b[39;00m \u001b[39mNone\u001b[39;00m \u001b[39mand\u001b[39;00m\n\u001b[1;32m    116\u001b[0m         errno\u001b[39m.\u001b[39merrorcode[err\u001b[39m.\u001b[39merrno] \u001b[39min\u001b[39;00m [\u001b[39m'\u001b[39m\u001b[39mENOENT\u001b[39m\u001b[39m'\u001b[39m, \u001b[39m'\u001b[39m\u001b[39mEACCES\u001b[39m\u001b[39m'\u001b[39m]):\n\u001b[1;32m    117\u001b[0m         \u001b[39m# Runs if the error is propagated due to no permission / file not found\u001b[39;00m\n\u001b[0;32m--> 118\u001b[0m         \u001b[39mraise\u001b[39;00m sys\u001b[39m.\u001b[39mexc_info()[\u001b[39m1\u001b[39m] \u001b[39mfrom\u001b[39;00m \u001b[39merr\u001b[39;00m\n\u001b[1;32m    119\u001b[0m     \u001b[39melse\u001b[39;00m:\n\u001b[1;32m    120\u001b[0m         \u001b[39m# Runs when the parser fails\u001b[39;00m\n\u001b[1;32m    121\u001b[0m         \u001b[39mraise\u001b[39;00m \u001b[39mIOError\u001b[39;00m(\u001b[39m\"\u001b[39m\u001b[39mFailed to load from the topology file \u001b[39m\u001b[39m{0}\u001b[39;00m\u001b[39m\"\u001b[39m\n\u001b[1;32m    122\u001b[0m                         \u001b[39m\"\u001b[39m\u001b[39m with parser \u001b[39m\u001b[39m{1}\u001b[39;00m\u001b[39m.\u001b[39m\u001b[39m\\n\u001b[39;00m\u001b[39m\"\u001b[39m\n\u001b[1;32m    123\u001b[0m                         \u001b[39m\"\u001b[39m\u001b[39mError: \u001b[39m\u001b[39m{2}\u001b[39;00m\u001b[39m\"\u001b[39m\u001b[39m.\u001b[39mformat(topology_file, parser, err))\n",
      "File \u001b[0;32m~/.python/current/lib/python3.10/site-packages/MDAnalysis/core/universe.py:110\u001b[0m, in \u001b[0;36m_topology_from_file_like\u001b[0;34m(topology_file, topology_format, **kwargs)\u001b[0m\n\u001b[1;32m    108\u001b[0m \u001b[39mtry\u001b[39;00m:\n\u001b[1;32m    109\u001b[0m     \u001b[39mwith\u001b[39;00m parser(topology_file) \u001b[39mas\u001b[39;00m p:\n\u001b[0;32m--> 110\u001b[0m         topology \u001b[39m=\u001b[39m p\u001b[39m.\u001b[39;49mparse(\u001b[39m*\u001b[39;49m\u001b[39m*\u001b[39;49mkwargs)\n\u001b[1;32m    111\u001b[0m \u001b[39mexcept\u001b[39;00m (\u001b[39mIOError\u001b[39;00m, \u001b[39mOSError\u001b[39;00m) \u001b[39mas\u001b[39;00m err:\n\u001b[1;32m    112\u001b[0m     \u001b[39m# There are 2 kinds of errors that might be raised here:\u001b[39;00m\n\u001b[1;32m    113\u001b[0m     \u001b[39m# one because the file isn't present\u001b[39;00m\n\u001b[1;32m    114\u001b[0m     \u001b[39m# or the permissions are bad, second when the parser fails\u001b[39;00m\n\u001b[1;32m    115\u001b[0m     \u001b[39mif\u001b[39;00m (err\u001b[39m.\u001b[39merrno \u001b[39mis\u001b[39;00m \u001b[39mnot\u001b[39;00m \u001b[39mNone\u001b[39;00m \u001b[39mand\u001b[39;00m\n\u001b[1;32m    116\u001b[0m         errno\u001b[39m.\u001b[39merrorcode[err\u001b[39m.\u001b[39merrno] \u001b[39min\u001b[39;00m [\u001b[39m'\u001b[39m\u001b[39mENOENT\u001b[39m\u001b[39m'\u001b[39m, \u001b[39m'\u001b[39m\u001b[39mEACCES\u001b[39m\u001b[39m'\u001b[39m]):\n\u001b[1;32m    117\u001b[0m         \u001b[39m# Runs if the error is propagated due to no permission / file not found\u001b[39;00m\n",
      "File \u001b[0;32m~/.python/current/lib/python3.10/site-packages/MDAnalysis/topology/PDBParser.py:210\u001b[0m, in \u001b[0;36mPDBParser.parse\u001b[0;34m(self, **kwargs)\u001b[0m\n\u001b[1;32m    203\u001b[0m \u001b[39mdef\u001b[39;00m \u001b[39mparse\u001b[39m(\u001b[39mself\u001b[39m, \u001b[39m*\u001b[39m\u001b[39m*\u001b[39mkwargs):\n\u001b[1;32m    204\u001b[0m \u001b[39m    \u001b[39m\u001b[39m\"\"\"Parse atom information from PDB file\u001b[39;00m\n\u001b[1;32m    205\u001b[0m \n\u001b[1;32m    206\u001b[0m \u001b[39m    Returns\u001b[39;00m\n\u001b[1;32m    207\u001b[0m \u001b[39m    -------\u001b[39;00m\n\u001b[1;32m    208\u001b[0m \u001b[39m    MDAnalysis Topology object\u001b[39;00m\n\u001b[1;32m    209\u001b[0m \u001b[39m    \"\"\"\u001b[39;00m\n\u001b[0;32m--> 210\u001b[0m     top \u001b[39m=\u001b[39m \u001b[39mself\u001b[39;49m\u001b[39m.\u001b[39;49m_parseatoms()\n\u001b[1;32m    212\u001b[0m     \u001b[39mtry\u001b[39;00m:\n\u001b[1;32m    213\u001b[0m         bonds \u001b[39m=\u001b[39m \u001b[39mself\u001b[39m\u001b[39m.\u001b[39m_parsebonds(top\u001b[39m.\u001b[39mids\u001b[39m.\u001b[39mvalues)\n",
      "File \u001b[0;32m~/.python/current/lib/python3.10/site-packages/MDAnalysis/topology/PDBParser.py:247\u001b[0m, in \u001b[0;36mPDBParser._parseatoms\u001b[0;34m(self)\u001b[0m\n\u001b[1;32m    245\u001b[0m \u001b[39mself\u001b[39m\u001b[39m.\u001b[39m_wrapped_serials \u001b[39m=\u001b[39m \u001b[39mFalse\u001b[39;00m  \u001b[39m# did serials go over 100k?\u001b[39;00m\n\u001b[1;32m    246\u001b[0m last_wrapped_serial \u001b[39m=\u001b[39m \u001b[39m100000\u001b[39m  \u001b[39m# if serials wrap, start from here\u001b[39;00m\n\u001b[0;32m--> 247\u001b[0m \u001b[39mwith\u001b[39;00m util\u001b[39m.\u001b[39mopenany(\u001b[39mself\u001b[39m\u001b[39m.\u001b[39mfilename) \u001b[39mas\u001b[39;00m f:\n\u001b[1;32m    248\u001b[0m     \u001b[39mfor\u001b[39;00m line \u001b[39min\u001b[39;00m f:\n\u001b[1;32m    249\u001b[0m         line \u001b[39m=\u001b[39m line\u001b[39m.\u001b[39mstrip()  \u001b[39m# Remove extra spaces\u001b[39;00m\n",
      "File \u001b[0;32m~/.python/current/lib/python3.10/contextlib.py:135\u001b[0m, in \u001b[0;36m_GeneratorContextManager.__enter__\u001b[0;34m(self)\u001b[0m\n\u001b[1;32m    133\u001b[0m \u001b[39mdel\u001b[39;00m \u001b[39mself\u001b[39m\u001b[39m.\u001b[39margs, \u001b[39mself\u001b[39m\u001b[39m.\u001b[39mkwds, \u001b[39mself\u001b[39m\u001b[39m.\u001b[39mfunc\n\u001b[1;32m    134\u001b[0m \u001b[39mtry\u001b[39;00m:\n\u001b[0;32m--> 135\u001b[0m     \u001b[39mreturn\u001b[39;00m \u001b[39mnext\u001b[39;49m(\u001b[39mself\u001b[39;49m\u001b[39m.\u001b[39;49mgen)\n\u001b[1;32m    136\u001b[0m \u001b[39mexcept\u001b[39;00m \u001b[39mStopIteration\u001b[39;00m:\n\u001b[1;32m    137\u001b[0m     \u001b[39mraise\u001b[39;00m \u001b[39mRuntimeError\u001b[39;00m(\u001b[39m\"\u001b[39m\u001b[39mgenerator didn\u001b[39m\u001b[39m'\u001b[39m\u001b[39mt yield\u001b[39m\u001b[39m\"\u001b[39m) \u001b[39mfrom\u001b[39;00m \u001b[39mNone\u001b[39;00m\n",
      "File \u001b[0;32m~/.python/current/lib/python3.10/site-packages/MDAnalysis/lib/util.py:318\u001b[0m, in \u001b[0;36mopenany\u001b[0;34m(datasource, mode, reset)\u001b[0m\n\u001b[1;32m    274\u001b[0m \u001b[39m@contextmanager\u001b[39m\n\u001b[1;32m    275\u001b[0m \u001b[39mdef\u001b[39;00m \u001b[39mopenany\u001b[39m(datasource, mode\u001b[39m=\u001b[39m\u001b[39m'\u001b[39m\u001b[39mrt\u001b[39m\u001b[39m'\u001b[39m, reset\u001b[39m=\u001b[39m\u001b[39mTrue\u001b[39;00m):\n\u001b[1;32m    276\u001b[0m \u001b[39m    \u001b[39m\u001b[39m\"\"\"Context manager for :func:`anyopen`.\u001b[39;00m\n\u001b[1;32m    277\u001b[0m \n\u001b[1;32m    278\u001b[0m \u001b[39m    Open the `datasource` and close it when the context of the :keyword:`with`\u001b[39;00m\n\u001b[0;32m   (...)\u001b[0m\n\u001b[1;32m    316\u001b[0m \u001b[39m    :func:`anyopen`\u001b[39;00m\n\u001b[1;32m    317\u001b[0m \u001b[39m    \"\"\"\u001b[39;00m\n\u001b[0;32m--> 318\u001b[0m     stream \u001b[39m=\u001b[39m anyopen(datasource, mode\u001b[39m=\u001b[39;49mmode, reset\u001b[39m=\u001b[39;49mreset)\n\u001b[1;32m    319\u001b[0m     \u001b[39mtry\u001b[39;00m:\n\u001b[1;32m    320\u001b[0m         \u001b[39myield\u001b[39;00m stream\n",
      "File \u001b[0;32m~/.python/current/lib/python3.10/site-packages/MDAnalysis/lib/util.py:398\u001b[0m, in \u001b[0;36manyopen\u001b[0;34m(datasource, mode, reset)\u001b[0m\n\u001b[1;32m    396\u001b[0m \u001b[39mfor\u001b[39;00m ext \u001b[39min\u001b[39;00m (\u001b[39m'\u001b[39m\u001b[39mbz2\u001b[39m\u001b[39m'\u001b[39m, \u001b[39m'\u001b[39m\u001b[39mgz\u001b[39m\u001b[39m'\u001b[39m, \u001b[39m'\u001b[39m\u001b[39m'\u001b[39m):  \u001b[39m# file == '' should be last\u001b[39;00m\n\u001b[1;32m    397\u001b[0m     openfunc \u001b[39m=\u001b[39m read_handlers[ext]\n\u001b[0;32m--> 398\u001b[0m     stream \u001b[39m=\u001b[39m _get_stream(datasource, openfunc, mode\u001b[39m=\u001b[39;49mmode)\n\u001b[1;32m    399\u001b[0m     \u001b[39mif\u001b[39;00m stream \u001b[39mis\u001b[39;00m \u001b[39mnot\u001b[39;00m \u001b[39mNone\u001b[39;00m:\n\u001b[1;32m    400\u001b[0m         \u001b[39mbreak\u001b[39;00m\n",
      "File \u001b[0;32m~/.python/current/lib/python3.10/site-packages/MDAnalysis/lib/util.py:440\u001b[0m, in \u001b[0;36m_get_stream\u001b[0;34m(filename, openfunction, mode)\u001b[0m\n\u001b[1;32m    435\u001b[0m \u001b[39mexcept\u001b[39;00m (\u001b[39mIOError\u001b[39;00m, \u001b[39mOSError\u001b[39;00m) \u001b[39mas\u001b[39;00m err:\n\u001b[1;32m    436\u001b[0m     \u001b[39m# An exception might be raised due to two reasons, first the openfunction is unable to open the file, in this\u001b[39;00m\n\u001b[1;32m    437\u001b[0m     \u001b[39m# case we have to ignore the error and return None. Second is when openfunction can't open the file because\u001b[39;00m\n\u001b[1;32m    438\u001b[0m     \u001b[39m# either the file isn't there or the permissions don't allow access.\u001b[39;00m\n\u001b[1;32m    439\u001b[0m     \u001b[39mif\u001b[39;00m errno\u001b[39m.\u001b[39merrorcode[err\u001b[39m.\u001b[39merrno] \u001b[39min\u001b[39;00m [\u001b[39m'\u001b[39m\u001b[39mENOENT\u001b[39m\u001b[39m'\u001b[39m, \u001b[39m'\u001b[39m\u001b[39mEACCES\u001b[39m\u001b[39m'\u001b[39m]:\n\u001b[0;32m--> 440\u001b[0m         \u001b[39mraise\u001b[39;00m sys\u001b[39m.\u001b[39mexc_info()[\u001b[39m1\u001b[39m] \u001b[39mfrom\u001b[39;00m \u001b[39merr\u001b[39;00m\n\u001b[1;32m    441\u001b[0m     \u001b[39mreturn\u001b[39;00m \u001b[39mNone\u001b[39;00m\n\u001b[1;32m    442\u001b[0m \u001b[39mif\u001b[39;00m mode\u001b[39m.\u001b[39mstartswith(\u001b[39m'\u001b[39m\u001b[39mr\u001b[39m\u001b[39m'\u001b[39m):\n\u001b[1;32m    443\u001b[0m     \u001b[39m# additional check for reading (eg can we uncompress) --- is this needed?\u001b[39;00m\n",
      "File \u001b[0;32m~/.python/current/lib/python3.10/site-packages/MDAnalysis/lib/util.py:434\u001b[0m, in \u001b[0;36m_get_stream\u001b[0;34m(filename, openfunction, mode)\u001b[0m\n\u001b[1;32m    432\u001b[0m \u001b[39m\u001b[39m\u001b[39m\"\"\"Return open stream if *filename* can be opened with *openfunction* or else ``None``.\"\"\"\u001b[39;00m\n\u001b[1;32m    433\u001b[0m \u001b[39mtry\u001b[39;00m:\n\u001b[0;32m--> 434\u001b[0m     stream \u001b[39m=\u001b[39m openfunction(filename, mode\u001b[39m=\u001b[39;49mmode)\n\u001b[1;32m    435\u001b[0m \u001b[39mexcept\u001b[39;00m (\u001b[39mIOError\u001b[39;00m, \u001b[39mOSError\u001b[39;00m) \u001b[39mas\u001b[39;00m err:\n\u001b[1;32m    436\u001b[0m     \u001b[39m# An exception might be raised due to two reasons, first the openfunction is unable to open the file, in this\u001b[39;00m\n\u001b[1;32m    437\u001b[0m     \u001b[39m# case we have to ignore the error and return None. Second is when openfunction can't open the file because\u001b[39;00m\n\u001b[1;32m    438\u001b[0m     \u001b[39m# either the file isn't there or the permissions don't allow access.\u001b[39;00m\n\u001b[1;32m    439\u001b[0m     \u001b[39mif\u001b[39;00m errno\u001b[39m.\u001b[39merrorcode[err\u001b[39m.\u001b[39merrno] \u001b[39min\u001b[39;00m [\u001b[39m'\u001b[39m\u001b[39mENOENT\u001b[39m\u001b[39m'\u001b[39m, \u001b[39m'\u001b[39m\u001b[39mEACCES\u001b[39m\u001b[39m'\u001b[39m]:\n",
      "File \u001b[0;32m~/.python/current/lib/python3.10/site-packages/MDAnalysis/lib/picklable_file_io.py:478\u001b[0m, in \u001b[0;36mbz2_pickle_open\u001b[0;34m(name, mode)\u001b[0m\n\u001b[1;32m    475\u001b[0m     \u001b[39mraise\u001b[39;00m \u001b[39mValueError\u001b[39;00m(\u001b[39m\"\u001b[39m\u001b[39mOnly read mode (\u001b[39m\u001b[39m'\u001b[39m\u001b[39mr\u001b[39m\u001b[39m'\u001b[39m\u001b[39m, \u001b[39m\u001b[39m'\u001b[39m\u001b[39mrt\u001b[39m\u001b[39m'\u001b[39m\u001b[39m, \u001b[39m\u001b[39m'\u001b[39m\u001b[39mrb\u001b[39m\u001b[39m'\u001b[39m\u001b[39m) \u001b[39m\u001b[39m\"\u001b[39m\n\u001b[1;32m    476\u001b[0m                      \u001b[39m\"\u001b[39m\u001b[39mfiles can be pickled.\u001b[39m\u001b[39m\"\u001b[39m)\n\u001b[1;32m    477\u001b[0m bz_mode \u001b[39m=\u001b[39m mode\u001b[39m.\u001b[39mreplace(\u001b[39m\"\u001b[39m\u001b[39mt\u001b[39m\u001b[39m\"\u001b[39m, \u001b[39m\"\u001b[39m\u001b[39m\"\u001b[39m)\n\u001b[0;32m--> 478\u001b[0m binary_file \u001b[39m=\u001b[39m BZ2Picklable(name, bz_mode)\n\u001b[1;32m    479\u001b[0m \u001b[39mif\u001b[39;00m \u001b[39m\"\u001b[39m\u001b[39mt\u001b[39m\u001b[39m\"\u001b[39m \u001b[39min\u001b[39;00m mode:\n\u001b[1;32m    480\u001b[0m     \u001b[39mreturn\u001b[39;00m TextIOPicklable(binary_file)\n",
      "File \u001b[0;32m~/.python/current/lib/python3.10/site-packages/MDAnalysis/lib/picklable_file_io.py:266\u001b[0m, in \u001b[0;36mBZ2Picklable.__init__\u001b[0;34m(self, name, mode)\u001b[0m\n\u001b[1;32m    264\u001b[0m \u001b[39mdef\u001b[39;00m \u001b[39m__init__\u001b[39m(\u001b[39mself\u001b[39m, name, mode\u001b[39m=\u001b[39m\u001b[39m'\u001b[39m\u001b[39mrb\u001b[39m\u001b[39m'\u001b[39m):\n\u001b[1;32m    265\u001b[0m     \u001b[39mself\u001b[39m\u001b[39m.\u001b[39m_bz_mode \u001b[39m=\u001b[39m mode\n\u001b[0;32m--> 266\u001b[0m     \u001b[39msuper\u001b[39;49m()\u001b[39m.\u001b[39;49m\u001b[39m__init__\u001b[39;49m(name, mode)\n",
      "File \u001b[0;32m~/.python/current/lib/python3.10/bz2.py:81\u001b[0m, in \u001b[0;36mBZ2File.__init__\u001b[0;34m(self, filename, mode, compresslevel)\u001b[0m\n\u001b[1;32m     78\u001b[0m     \u001b[39mraise\u001b[39;00m \u001b[39mValueError\u001b[39;00m(\u001b[39m\"\u001b[39m\u001b[39mInvalid mode: \u001b[39m\u001b[39m%r\u001b[39;00m\u001b[39m\"\u001b[39m \u001b[39m%\u001b[39m (mode,))\n\u001b[1;32m     80\u001b[0m \u001b[39mif\u001b[39;00m \u001b[39misinstance\u001b[39m(filename, (\u001b[39mstr\u001b[39m, \u001b[39mbytes\u001b[39m, os\u001b[39m.\u001b[39mPathLike)):\n\u001b[0;32m---> 81\u001b[0m     \u001b[39mself\u001b[39m\u001b[39m.\u001b[39m_fp \u001b[39m=\u001b[39m _builtin_open(filename, mode)\n\u001b[1;32m     82\u001b[0m     \u001b[39mself\u001b[39m\u001b[39m.\u001b[39m_closefp \u001b[39m=\u001b[39m \u001b[39mTrue\u001b[39;00m\n\u001b[1;32m     83\u001b[0m     \u001b[39mself\u001b[39m\u001b[39m.\u001b[39m_mode \u001b[39m=\u001b[39m mode_code\n",
      "\u001b[0;31mFileNotFoundError\u001b[0m: [Errno 2] No such file or directory: 'PDB_tubuline.pdb'"
     ]
    }
   ],
   "source": [
    "# Importing the MDAnalysis package.\n",
    "import MDAnalysis as mda\n",
    "\n",
    "# Creating the Universe object.\n",
    "u = mda.Universe('PDB_tubuline.pdb', 'trajectoire_tubuline.dcd')\n",
    "\n",
    "# Create a selection of atoms to work with.\n",
    "ag = u.atoms.select_atoms('backbone')\n",
    "\n",
    "# Select all solvent within a set distance from protein atoms.\n",
    "ag = u.select_atoms('resname SOL and around 5.0 protein')\n",
    "\n",
    "# Select all heavy atoms in the first 20 residues.\n",
    "ag = u.select_atoms('resid 1:20 and not prop mass < 10.0')\n",
    "\n",
    "# Use a preexisting AtomGroup as part of another selection.\n",
    "sel1 = u.select_atoms('name N and not resname MET')\n",
    "sel2 = u.select_atoms('around 2.5 group Nsel', Nsel=sel1)\n",
    "\n",
    "# Perform a selection on another AtomGroup.\n",
    "sel1 = u.select_atoms('around 5.0 protein')\n",
    "sel2 = sel1.select_atoms('type O')"
   ]
  }
 ],
 "metadata": {
  "kernelspec": {
   "display_name": "Python 3",
   "language": "python",
   "name": "python3"
  },
  "language_info": {
   "codemirror_mode": {
    "name": "ipython",
    "version": 3
   },
   "file_extension": ".py",
   "mimetype": "text/x-python",
   "name": "python",
   "nbconvert_exporter": "python",
   "pygments_lexer": "ipython3",
   "version": "3.10.8"
  }
 },
 "nbformat": 4,
 "nbformat_minor": 2
}
